         ^
SyntaxError: invalid syntax
Performing system checks...

System check identified no issues (0 silenced).
September 30, 2017 - 04:01:12
Django version 1.11.5, using settings 'samplesite.settings'
Starting development server at http://127.0.0.1:8000/
Quit the server with CONTROL-C.
Performing system checks...

System check identified no issues (0 silenced).
September 30, 2017 - 04:01:40
Django version 1.11.5, using settings 'samplesite.settings'
Starting development server at http://127.0.0.1:8000/
Quit the server with CONTROL-C.
Performing system checks...

System check identified no issues (0 silenced).
September 30, 2017 - 04:02:22
Django version 1.11.5, using settings 'samplesite.settings'
Starting development server at http://127.0.0.1:8000/
Quit the server with CONTROL-C.
Performing system checks...

System check identified no issues (0 silenced).
September 30, 2017 - 04:02:27
Django version 1.11.5, using settings 'samplesite.settings'
Starting development server at http://127.0.0.1:8000/
Quit the server with CONTROL-C.
^Cyangzhiqiongs-MacBook-Pro:samplesite root# python3 manage.py shell
Python 3.6.2 (v3.6.2:5fd33b5926, Jul 16 2017, 20:11:06) 
[GCC 4.2.1 (Apple Inc. build 5666) (dot 3)] on darwin
Type "help", "copyright", "credits" or "license" for more information.
(InteractiveConsole)
>>> import datetime
>>> from d
datetime def      del      delattr( dict(    dir(     divmod( 
>>> from django.utils import timezone
>>> from polls.models import Question
>>> future_question = Question(pub_date=timezone.now()+datetime.timedelta(days=30))
>>> future_question.was_published_recently()
True
>>> quit()
yangzhiqiongs-MacBook-Pro:samplesite root# 
yangzhiqiongs-MacBook-Pro:samplesite root# 
yangzhiqiongs-MacBook-Pro:samplesite root# python3 manage.py test polls
Creating test database for alias 'default'...
System check identified no issues (0 silenced).
E
======================================================================
ERROR: polls.tests (unittest.loader._FailedTest)
----------------------------------------------------------------------
ImportError: Failed to import test module: polls.tests
Traceback (most recent call last):
  File "/Library/Frameworks/Python.framework/Versions/3.6/lib/python3.6/unittest/loader.py", line 428, in _find_test_path
    module = self._get_module_from_name(name)
  File "/Library/Frameworks/Python.framework/Versions/3.6/lib/python3.6/unittest/loader.py", line 369, in _get_module_from_name
    __import__(name)
  File "/private/var/root/python_practise/Django/samplesite/polls/tests.py", line 5, in <module>
    from diango.utils import  timezone
ModuleNotFoundError: No module named 'diango'


----------------------------------------------------------------------
Ran 1 test in 0.000s

FAILED (errors=1)
Destroying test database for alias 'default'...
yangzhiqiongs-MacBook-Pro:samplesite root# python3 manage.py test polls
Creating test database for alias 'default'...
System check identified no issues (0 silenced).
E
======================================================================
ERROR: test_was_published_recently_with_future_question (polls.tests.QuestionMethodTests)
----------------------------------------------------------------------
Traceback (most recent call last):
  File "/private/var/root/python_practise/Django/samplesite/polls/tests.py", line 12, in test_was_published_recently_with_future_question
    time = timezone,now() + datetime.timedelta(days=30)
NameError: name 'now' is not defined

----------------------------------------------------------------------
Ran 1 test in 0.001s

FAILED (errors=1)
Destroying test database for alias 'default'...
yangzhiqiongs-MacBook-Pro:samplesite root# python3 manage.py test polls
Creating test database for alias 'default'...
System check identified no issues (0 silenced).
F
======================================================================
FAIL: test_was_published_recently_with_future_question (polls.tests.QuestionMethodTests)
----------------------------------------------------------------------
Traceback (most recent call last):
  File "/private/var/root/python_practise/Django/samplesite/polls/tests.py", line 14, in test_was_published_recently_with_future_question
    self.assertIs(future_question.was_published_recently(),False)
AssertionError: True is not False

----------------------------------------------------------------------
Ran 1 test in 0.001s

FAILED (failures=1)
Destroying test database for alias 'default'...
yangzhiqiongs-MacBook-Pro:samplesite root# python3 manage.py test polls
Creating test database for alias 'default'...
System check identified no issues (0 silenced).
.
----------------------------------------------------------------------
Ran 1 test in 0.001s

OK
Destroying test database for alias 'default'...
yangzhiqiongs-MacBook-Pro:samplesite root# python3 manage.py test polls
Creating test database for alias 'default'...
System check identified no issues (0 silenced).
...
----------------------------------------------------------------------
Ran 3 tests in 0.001s

OK
Destroying test database for alias 'default'...
yangzhiqiongs-MacBook-Pro:samplesite root# 
yangzhiqiongs-MacBook-Pro:samplesite root# 
yangzhiqiongs-MacBook-Pro:samplesite root# python3 manage.py shell
Python 3.6.2 (v3.6.2:5fd33b5926, Jul 16 2017, 20:11:06) 
[GCC 4.2.1 (Apple Inc. build 5666) (dot 3)] on darwin
Type "help", "copyright", "credits" or "license" for more information.
(InteractiveConsole)
>>> from django.test.utils import setup_test_environment
>>> setup_test_environment()
>>> from django.test import Client
>>> client = Client()
>>> response = client.get('/')
>>> response.status.code
Traceback (most recent call last):
  File "<console>", line 1, in <module>
AttributeError: 'HttpResponse' object has no attribute 'status'
>>> response.status_code
200
>>> 
>>> 
>>> 
>>> 
>>> from django.urls import reverse
>>> response = client.get(reverse('polls:index'))
Internal Server Error: /polls/
Traceback (most recent call last):
  File "/Library/Frameworks/Python.framework/Versions/3.6/lib/python3.6/site-packages/django/core/handlers/exception.py", line 41, in inner
    response = get_response(request)
  File "/Library/Frameworks/Python.framework/Versions/3.6/lib/python3.6/site-packages/django/core/handlers/base.py", line 187, in _get_response
    response = self.process_exception_by_middleware(e, request)
  File "/Library/Frameworks/Python.framework/Versions/3.6/lib/python3.6/site-packages/django/core/handlers/base.py", line 185, in _get_response
    response = wrapped_callback(request, *callback_args, **callback_kwargs)
  File "/Library/Frameworks/Python.framework/Versions/3.6/lib/python3.6/site-packages/django/views/generic/base.py", line 68, in view
    return self.dispatch(request, *args, **kwargs)
  File "/Library/Frameworks/Python.framework/Versions/3.6/lib/python3.6/site-packages/django/views/generic/base.py", line 88, in dispatch
    return handler(request, *args, **kwargs)
  File "/Library/Frameworks/Python.framework/Versions/3.6/lib/python3.6/site-packages/django/views/generic/list.py", line 160, in get
    self.object_list = self.get_queryset()
  File "/private/var/root/python_practise/Django/samplesite/polls/views.py", line 25, in get_queryset
    return Question.objects.orderby('-pub_date')[:5]
AttributeError: 'Manager' object has no attribute 'orderby'
Traceback (most recent call last):
  File "<console>", line 1, in <module>
  File "/Library/Frameworks/Python.framework/Versions/3.6/lib/python3.6/site-packages/django/test/client.py", line 536, in get
    **extra)
  File "/Library/Frameworks/Python.framework/Versions/3.6/lib/python3.6/site-packages/django/test/client.py", line 340, in get
    return self.generic('GET', path, secure=secure, **r)
  File "/Library/Frameworks/Python.framework/Versions/3.6/lib/python3.6/site-packages/django/test/client.py", line 416, in generic
    return self.request(**r)
  File "/Library/Frameworks/Python.framework/Versions/3.6/lib/python3.6/site-packages/django/test/client.py", line 501, in request
    six.reraise(*exc_info)
  File "/Library/Frameworks/Python.framework/Versions/3.6/lib/python3.6/site-packages/django/utils/six.py", line 686, in reraise
    raise value
  File "/Library/Frameworks/Python.framework/Versions/3.6/lib/python3.6/site-packages/django/core/handlers/exception.py", line 41, in inner
    response = get_response(request)
  File "/Library/Frameworks/Python.framework/Versions/3.6/lib/python3.6/site-packages/django/core/handlers/base.py", line 187, in _get_response
    response = self.process_exception_by_middleware(e, request)
  File "/Library/Frameworks/Python.framework/Versions/3.6/lib/python3.6/site-packages/django/core/handlers/base.py", line 185, in _get_response
    response = wrapped_callback(request, *callback_args, **callback_kwargs)
  File "/Library/Frameworks/Python.framework/Versions/3.6/lib/python3.6/site-packages/django/views/generic/base.py", line 68, in view
    return self.dispatch(request, *args, **kwargs)
  File "/Library/Frameworks/Python.framework/Versions/3.6/lib/python3.6/site-packages/django/views/generic/base.py", line 88, in dispatch
    return handler(request, *args, **kwargs)
  File "/Library/Frameworks/Python.framework/Versions/3.6/lib/python3.6/site-packages/django/views/generic/list.py", line 160, in get
    self.object_list = self.get_queryset()
  File "/private/var/root/python_practise/Django/samplesite/polls/views.py", line 25, in get_queryset
    return Question.objects.orderby('-pub_date')[:5]
AttributeError: 'Manager' object has no attribute 'orderby'
>>> from django.urls import reverse
>>> response = client.get(reverse('polls:index'))
Internal Server Error: /polls/
Traceback (most recent call last):
  File "/Library/Frameworks/Python.framework/Versions/3.6/lib/python3.6/site-packages/django/core/handlers/exception.py", line 41, in inner
    response = get_response(request)
  File "/Library/Frameworks/Python.framework/Versions/3.6/lib/python3.6/site-packages/django/core/handlers/base.py", line 187, in _get_response
    response = self.process_exception_by_middleware(e, request)
  File "/Library/Frameworks/Python.framework/Versions/3.6/lib/python3.6/site-packages/django/core/handlers/base.py", line 185, in _get_response
    response = wrapped_callback(request, *callback_args, **callback_kwargs)
  File "/Library/Frameworks/Python.framework/Versions/3.6/lib/python3.6/site-packages/django/views/generic/base.py", line 68, in view
    return self.dispatch(request, *args, **kwargs)
  File "/Library/Frameworks/Python.framework/Versions/3.6/lib/python3.6/site-packages/django/views/generic/base.py", line 88, in dispatch
    return handler(request, *args, **kwargs)
  File "/Library/Frameworks/Python.framework/Versions/3.6/lib/python3.6/site-packages/django/views/generic/list.py", line 160, in get
    self.object_list = self.get_queryset()
  File "/private/var/root/python_practise/Django/samplesite/polls/views.py", line 25, in get_queryset
    return Question.objects.order_by('-pub_date')[:5]
AttributeError: 'Manager' object has no attribute 'orderby'
Traceback (most recent call last):
  File "<console>", line 1, in <module>
  File "/Library/Frameworks/Python.framework/Versions/3.6/lib/python3.6/site-packages/django/test/client.py", line 536, in get
    **extra)
  File "/Library/Frameworks/Python.framework/Versions/3.6/lib/python3.6/site-packages/django/test/client.py", line 340, in get
    return self.generic('GET', path, secure=secure, **r)
  File "/Library/Frameworks/Python.framework/Versions/3.6/lib/python3.6/site-packages/django/test/client.py", line 416, in generic
    return self.request(**r)
  File "/Library/Frameworks/Python.framework/Versions/3.6/lib/python3.6/site-packages/django/test/client.py", line 501, in request
    six.reraise(*exc_info)
  File "/Library/Frameworks/Python.framework/Versions/3.6/lib/python3.6/site-packages/django/utils/six.py", line 686, in reraise
    raise value
  File "/Library/Frameworks/Python.framework/Versions/3.6/lib/python3.6/site-packages/django/core/handlers/exception.py", line 41, in inner
    response = get_response(request)
  File "/Library/Frameworks/Python.framework/Versions/3.6/lib/python3.6/site-packages/django/core/handlers/base.py", line 187, in _get_response
    response = self.process_exception_by_middleware(e, request)
  File "/Library/Frameworks/Python.framework/Versions/3.6/lib/python3.6/site-packages/django/core/handlers/base.py", line 185, in _get_response
    response = wrapped_callback(request, *callback_args, **callback_kwargs)
  File "/Library/Frameworks/Python.framework/Versions/3.6/lib/python3.6/site-packages/django/views/generic/base.py", line 68, in view
    return self.dispatch(request, *args, **kwargs)
  File "/Library/Frameworks/Python.framework/Versions/3.6/lib/python3.6/site-packages/django/views/generic/base.py", line 88, in dispatch
    return handler(request, *args, **kwargs)
  File "/Library/Frameworks/Python.framework/Versions/3.6/lib/python3.6/site-packages/django/views/generic/list.py", line 160, in get
    self.object_list = self.get_queryset()
  File "/private/var/root/python_practise/Django/samplesite/polls/views.py", line 25, in get_queryset
    return Question.objects.order_by('-pub_date')[:5]
AttributeError: 'Manager' object has no attribute 'orderby'
>>> response = client.get(reverse('polls:index'))
Internal Server Error: /polls/
Traceback (most recent call last):
  File "/Library/Frameworks/Python.framework/Versions/3.6/lib/python3.6/site-packages/django/core/handlers/exception.py", line 41, in inner
    response = get_response(request)
  File "/Library/Frameworks/Python.framework/Versions/3.6/lib/python3.6/site-packages/django/core/handlers/base.py", line 187, in _get_response
    response = self.process_exception_by_middleware(e, request)
  File "/Library/Frameworks/Python.framework/Versions/3.6/lib/python3.6/site-packages/django/core/handlers/base.py", line 185, in _get_response
    response = wrapped_callback(request, *callback_args, **callback_kwargs)
  File "/Library/Frameworks/Python.framework/Versions/3.6/lib/python3.6/site-packages/django/views/generic/base.py", line 68, in view
    return self.dispatch(request, *args, **kwargs)
  File "/Library/Frameworks/Python.framework/Versions/3.6/lib/python3.6/site-packages/django/views/generic/base.py", line 88, in dispatch
    return handler(request, *args, **kwargs)
  File "/Library/Frameworks/Python.framework/Versions/3.6/lib/python3.6/site-packages/django/views/generic/list.py", line 160, in get
    self.object_list = self.get_queryset()
  File "/private/var/root/python_practise/Django/samplesite/polls/views.py", line 25, in get_queryset
    return Question.objects.order_by('-pub_date')[:5]
AttributeError: 'Manager' object has no attribute 'orderby'
Traceback (most recent call last):
  File "<console>", line 1, in <module>
  File "/Library/Frameworks/Python.framework/Versions/3.6/lib/python3.6/site-packages/django/test/client.py", line 536, in get
    **extra)
  File "/Library/Frameworks/Python.framework/Versions/3.6/lib/python3.6/site-packages/django/test/client.py", line 340, in get
    return self.generic('GET', path, secure=secure, **r)
  File "/Library/Frameworks/Python.framework/Versions/3.6/lib/python3.6/site-packages/django/test/client.py", line 416, in generic
    return self.request(**r)
  File "/Library/Frameworks/Python.framework/Versions/3.6/lib/python3.6/site-packages/django/test/client.py", line 501, in request
    six.reraise(*exc_info)
  File "/Library/Frameworks/Python.framework/Versions/3.6/lib/python3.6/site-packages/django/utils/six.py", line 686, in reraise
    raise value
  File "/Library/Frameworks/Python.framework/Versions/3.6/lib/python3.6/site-packages/django/core/handlers/exception.py", line 41, in inner
    response = get_response(request)
  File "/Library/Frameworks/Python.framework/Versions/3.6/lib/python3.6/site-packages/django/core/handlers/base.py", line 187, in _get_response
    response = self.process_exception_by_middleware(e, request)
  File "/Library/Frameworks/Python.framework/Versions/3.6/lib/python3.6/site-packages/django/core/handlers/base.py", line 185, in _get_response
    response = wrapped_callback(request, *callback_args, **callback_kwargs)
  File "/Library/Frameworks/Python.framework/Versions/3.6/lib/python3.6/site-packages/django/views/generic/base.py", line 68, in view
    return self.dispatch(request, *args, **kwargs)
  File "/Library/Frameworks/Python.framework/Versions/3.6/lib/python3.6/site-packages/django/views/generic/base.py", line 88, in dispatch
    return handler(request, *args, **kwargs)
  File "/Library/Frameworks/Python.framework/Versions/3.6/lib/python3.6/site-packages/django/views/generic/list.py", line 160, in get
    self.object_list = self.get_queryset()
  File "/private/var/root/python_practise/Django/samplesite/polls/views.py", line 25, in get_queryset
    return Question.objects.order_by('-pub_date')[:5]
AttributeError: 'Manager' object has no attribute 'orderby'
>>> 
>>> 
>>> 
>>> 
>>> exit
Use exit() or Ctrl-D (i.e. EOF) to exit
>>> quit()
yangzhiqiongs-MacBook-Pro:samplesite root# python3 manage.py shell
Python 3.6.2 (v3.6.2:5fd33b5926, Jul 16 2017, 20:11:06) 
[GCC 4.2.1 (Apple Inc. build 5666) (dot 3)] on darwin
Type "help", "copyright", "credits" or "license" for more information.
(InteractiveConsole)
>>> 
>>> 
>>> from django.urls import reverse
>>> from django.test.utils import setup_test_environment
>>> setup_test_environment(

>>> setup_test_environment()
>>> 
>>> 
>>> from django.test import Client
>>> client = Client()
>>> response = client.get('/')
>>> response.status_code
200
>>> 
>>> response = client.get(reverse('polls:index'))
>>> response.status_code
200
>>> response.content
b'\n    <p>No polls are available</p>\n\n\n'
>>> response.context['latest_question_list']
<QuerySet [<Question: What's up>]>
>>> 
>>> quit()
yangzhiqiongs-MacBook-Pro:samplesite root# python3 manage.py runserver
Unhandled exception in thread started by <function check_errors.<locals>.wrapper at 0x1040bf378>
Traceback (most recent call last):
  File "/Library/Frameworks/Python.framework/Versions/3.6/lib/python3.6/site-packages/django/utils/autoreload.py", line 228, in wrapper
    fn(*args, **kwargs)
  File "/Library/Frameworks/Python.framework/Versions/3.6/lib/python3.6/site-packages/django/core/management/commands/runserver.py", line 117, in inner_run
    autoreload.raise_last_exception()
  File "/Library/Frameworks/Python.framework/Versions/3.6/lib/python3.6/site-packages/django/utils/autoreload.py", line 251, in raise_last_exception
    six.reraise(*_exception)
  File "/Library/Frameworks/Python.framework/Versions/3.6/lib/python3.6/site-packages/django/utils/six.py", line 685, in reraise
    raise value.with_traceback(tb)
  File "/Library/Frameworks/Python.framework/Versions/3.6/lib/python3.6/site-packages/django/utils/autoreload.py", line 228, in wrapper
    fn(*args, **kwargs)
  File "/Library/Frameworks/Python.framework/Versions/3.6/lib/python3.6/site-packages/django/__init__.py", line 27, in setup
    apps.populate(settings.INSTALLED_APPS)
  File "/Library/Frameworks/Python.framework/Versions/3.6/lib/python3.6/site-packages/django/apps/registry.py", line 116, in populate
    app_config.ready()
  File "/Library/Frameworks/Python.framework/Versions/3.6/lib/python3.6/site-packages/django/contrib/admin/apps.py", line 23, in ready
    self.module.autodiscover()
  File "/Library/Frameworks/Python.framework/Versions/3.6/lib/python3.6/site-packages/django/contrib/admin/__init__.py", line 26, in autodiscover
    autodiscover_modules('admin', register_to=site)
  File "/Library/Frameworks/Python.framework/Versions/3.6/lib/python3.6/site-packages/django/utils/module_loading.py", line 50, in autodiscover_modules
    import_module('%s.%s' % (app_config.name, module_to_search))
  File "/Library/Frameworks/Python.framework/Versions/3.6/lib/python3.6/importlib/__init__.py", line 126, in import_module
    return _bootstrap._gcd_import(name[level:], package, level)
  File "<frozen importlib._bootstrap>", line 978, in _gcd_import
  File "<frozen importlib._bootstrap>", line 961, in _find_and_load
  File "<frozen importlib._bootstrap>", line 950, in _find_and_load_unlocked
  File "<frozen importlib._bootstrap>", line 655, in _load_unlocked
  File "<frozen importlib._bootstrap_external>", line 678, in exec_module
  File "<frozen importlib._bootstrap>", line 205, in _call_with_frames_removed
  File "/private/var/root/python_practise/Django/samplesite/polls/admin.py", line 9, in <module>
    admin.site.register(Choice)
NameError: name 'Choice' is not defined
Performing system checks...

System check identified no issues (0 silenced).
September 30, 2017 - 04:41:19
Django version 1.11.5, using settings 'samplesite.settings'
Starting development server at http://127.0.0.1:8000/
Quit the server with CONTROL-C.
[30/Sep/2017 04:42:11] "GET /polls/ HTTP/1.1" 200 37
[30/Sep/2017 04:42:12] "GET / HTTP/1.1" 200 14
[30/Sep/2017 04:42:12] "GET /admin/ HTTP/1.1" 200 3818
[30/Sep/2017 04:42:13] "GET /admin/ HTTP/1.1" 200 3818
[30/Sep/2017 04:42:14] "GET /admin/ HTTP/1.1" 200 3818
[30/Sep/2017 04:42:16] "GET /admin/polls/choice/ HTTP/1.1" 200 4627
[30/Sep/2017 04:42:16] "GET /static/admin/css/changelists.css HTTP/1.1" 304 0
[30/Sep/2017 04:42:16] "GET /static/admin/js/core.js HTTP/1.1" 304 0
[30/Sep/2017 04:42:16] "GET /static/admin/js/vendor/jquery/jquery.js HTTP/1.1" 304 0
[30/Sep/2017 04:42:16] "GET /static/admin/js/admin/RelatedObjectLookups.js HTTP/1.1" 304 0
[30/Sep/2017 04:42:16] "GET /admin/jsi18n/ HTTP/1.1" 200 3189
[30/Sep/2017 04:42:16] "GET /static/admin/js/jquery.init.js HTTP/1.1" 304 0
[30/Sep/2017 04:42:16] "GET /static/admin/js/actions.js HTTP/1.1" 304 0
[30/Sep/2017 04:42:16] "GET /static/admin/js/urlify.js HTTP/1.1" 304 0
[30/Sep/2017 04:42:16] "GET /static/admin/js/prepopulate.js HTTP/1.1" 304 0
[30/Sep/2017 04:42:16] "GET /static/admin/js/vendor/xregexp/xregexp.js HTTP/1.1" 304 0
[30/Sep/2017 04:42:16] "GET /static/admin/img/tooltag-add.svg HTTP/1.1" 304 0
[30/Sep/2017 04:42:20] "GET /admin/polls/choice/3/change/ HTTP/1.1" 200 5710
[30/Sep/2017 04:42:20] "GET /static/admin/js/change_form.js HTTP/1.1" 200 712
[30/Sep/2017 04:42:20] "GET /static/admin/css/forms.css HTTP/1.1" 200 8173
[30/Sep/2017 04:42:20] "GET /static/admin/js/prepopulate_init.js HTTP/1.1" 200 495
[30/Sep/2017 04:42:20] "GET /admin/jsi18n/ HTTP/1.1" 200 3189
[30/Sep/2017 04:42:20] "GET /static/admin/css/widgets.css HTTP/1.1" 200 10340
[30/Sep/2017 04:42:33] "GET /admin/polls/choice/3/change/ HTTP/1.1" 200 5710
[30/Sep/2017 04:42:33] "GET /admin/jsi18n/ HTTP/1.1" 200 3189
[30/Sep/2017 04:42:39] "GET /admin/polls/question/add/?_to_field=id&_popup=1 HTTP/1.1" 200 3732
[30/Sep/2017 04:42:39] "GET /static/admin/js/admin/DateTimeShortcuts.js HTTP/1.1" 200 20529
[30/Sep/2017 04:42:39] "GET /static/admin/js/calendar.js HTTP/1.1" 200 7790
[30/Sep/2017 04:42:39] "GET /admin/jsi18n/ HTTP/1.1" 200 3189
[30/Sep/2017 04:42:39] "GET /static/admin/img/icon-clock.svg HTTP/1.1" 200 677
[30/Sep/2017 04:42:39] "GET /static/admin/img/icon-calendar.svg HTTP/1.1" 200 1086
[30/Sep/2017 04:42:51] "GET /static/admin/img/calendar-icons.svg HTTP/1.1" 200 1094
[30/Sep/2017 04:42:54] "POST /admin/polls/question/add/?_to_field=id&_popup=1 HTTP/1.1" 200 365
[30/Sep/2017 04:42:54] "GET /static/admin/js/popup_response.js HTTP/1.1" 200 569
[30/Sep/2017 04:43:03] "POST /admin/polls/choice/3/change/ HTTP/1.1" 302 0
[30/Sep/2017 04:43:03] "GET /admin/polls/choice/ HTTP/1.1" 200 4815
[30/Sep/2017 04:43:03] "GET /admin/jsi18n/ HTTP/1.1" 200 3189
[30/Sep/2017 04:43:03] "GET /static/admin/img/icon-yes.svg HTTP/1.1" 304 0
[30/Sep/2017 04:43:10] "GET /admin/polls/choice/3/change/ HTTP/1.1" 200 5761
[30/Sep/2017 04:43:10] "GET /admin/jsi18n/ HTTP/1.1" 200 3189
[30/Sep/2017 04:43:20] "POST /admin/polls/choice/3/change/ HTTP/1.1" 302 0
[30/Sep/2017 04:43:20] "GET /admin/polls/choice/ HTTP/1.1" 200 4815
[30/Sep/2017 04:43:20] "GET /admin/jsi18n/ HTTP/1.1" 200 3189
[30/Sep/2017 04:43:42] "GET /admin/polls/choice/3/change/ HTTP/1.1" 200 5766
[30/Sep/2017 04:43:45] "GET /admin/polls/choice/ HTTP/1.1" 200 4627
[30/Sep/2017 04:43:45] "GET /admin/jsi18n/ HTTP/1.1" 200 3189
[30/Sep/2017 04:43:51] "GET /admin/polls/ HTTP/1.1" 200 2603
[30/Sep/2017 04:43:53] "GET /admin/polls/question/ HTTP/1.1" 200 4419
[30/Sep/2017 04:43:53] "GET /admin/jsi18n/ HTTP/1.1" 200 3189
[30/Sep/2017 04:43:56] "GET /admin/polls/question/2/change/ HTTP/1.1" 200 4964
[30/Sep/2017 04:43:56] "GET /admin/jsi18n/ HTTP/1.1" 200 3189
[30/Sep/2017 04:43:59] "GET /admin/polls/question/1/change/ HTTP/1.1" 200 4970
[30/Sep/2017 04:43:59] "GET /admin/jsi18n/ HTTP/1.1" 200 3189
Performing system checks...

System check identified no issues (0 silenced).
September 30, 2017 - 05:58:48
Django version 1.11.5, using settings 'samplesite.settings'
Starting development server at http://127.0.0.1:8000/
Quit the server with CONTROL-C.
Performing system checks...

System check identified no issues (0 silenced).
September 30, 2017 - 05:59:20
Django version 1.11.5, using settings 'samplesite.settings'
Starting development server at http://127.0.0.1:8000/
Quit the server with CONTROL-C.
Performing system checks...

System check identified no issues (0 silenced).
September 30, 2017 - 05:59:24
Django version 1.11.5, using settings 'samplesite.settings'
Starting development server at http://127.0.0.1:8000/
Quit the server with CONTROL-C.
Performing system checks...

System check identified no issues (0 silenced).
September 30, 2017 - 05:59:33
Django version 1.11.5, using settings 'samplesite.settings'
Starting development server at http://127.0.0.1:8000/
Quit the server with CONTROL-C.
Performing system checks...

System check identified no issues (0 silenced).
September 30, 2017 - 05:59:41
Django version 1.11.5, using settings 'samplesite.settings'
Starting development server at http://127.0.0.1:8000/
Quit the server with CONTROL-C.
Performing system checks...

System check identified no issues (0 silenced).
September 30, 2017 - 05:59:44
Django version 1.11.5, using settings 'samplesite.settings'
Starting development server at http://127.0.0.1:8000/
Quit the server with CONTROL-C.
Performing system checks...

System check identified no issues (0 silenced).
September 30, 2017 - 05:59:54
Django version 1.11.5, using settings 'samplesite.settings'
Starting development server at http://127.0.0.1:8000/
Quit the server with CONTROL-C.


